13:07:37 [Q] INFO Q Cluster eight-maine-mississippi-xray starting.
13:07:37 [Q] INFO Process-1:1 ready for work at 129247
13:07:37 [Q] INFO Process-1:2 monitoring at 129248
13:07:37 [Q] INFO 129247 will use cpu [0]
13:07:37 [Q] INFO Process-1 guarding cluster eight-maine-mississippi-xray
13:07:37 [Q] INFO Q Cluster eight-maine-mississippi-xray running.
13:07:37 [Q] INFO Process-1:3 pushing tasks at 129249
--- Logging error ---
Traceback (most recent call last):
  File "/usr/local/lib/python3.10/site-packages/django_q/cluster.py", line 356, in pusher
    task = SignedPackage.loads(task[1])
  File "/usr/local/lib/python3.10/site-packages/django_q/signing.py", line 25, in loads
    return signing.loads(
  File "/usr/local/lib/python3.10/site-packages/django_q/core_signing.py", line 35, in loads
    base64d = force_bytes(TimestampSigner(key, salt=salt).unsign(s, max_age=max_age))
  File "/usr/local/lib/python3.10/site-packages/django_q/core_signing.py", line 70, in unsign
    result = super(TimestampSigner, self).unsign(value)
  File "/usr/local/lib/python3.10/site-packages/django_q/core_signing.py", line 55, in unsign
    raise BadSignature('Signature "%s" does not match' % sig)
django.core.signing.BadSignature: Signature "AU9Rdt5g7MKNuJZGn2WO4dMQMkcKD4k3a-IPty2EqdQ" does not match

During handling of the above exception, another exception occurred:

Traceback (most recent call last):
  File "/usr/local/lib/python3.10/logging/__init__.py", line 1100, in emit
    msg = self.format(record)
  File "/usr/local/lib/python3.10/logging/__init__.py", line 943, in format
    return fmt.format(record)
  File "/usr/local/lib/python3.10/logging/__init__.py", line 678, in format
    record.message = record.getMessage()
  File "/usr/local/lib/python3.10/logging/__init__.py", line 368, in getMessage
    msg = msg % self.args
TypeError: not all arguments converted during string formatting
Call stack:
  File "/home/VideoWatchEarnBot/server/manage.py", line 22, in <module>
    main()
  File "/home/VideoWatchEarnBot/server/manage.py", line 18, in main
    execute_from_command_line(sys.argv)
  File "/usr/local/lib/python3.10/site-packages/django/core/management/__init__.py", line 446, in execute_from_command_line
    utility.execute()
  File "/usr/local/lib/python3.10/site-packages/django/core/management/__init__.py", line 440, in execute
    self.fetch_command(subcommand).run_from_argv(self.argv)
  File "/usr/local/lib/python3.10/site-packages/django/core/management/base.py", line 414, in run_from_argv
    self.execute(*args, **cmd_options)
  File "/usr/local/lib/python3.10/site-packages/django/core/management/base.py", line 460, in execute
    output = self.handle(*args, **options)
  File "/usr/local/lib/python3.10/site-packages/django_q/management/commands/qcluster.py", line 22, in handle
    q.start()
  File "/usr/local/lib/python3.10/site-packages/django_q/cluster.py", line 78, in start
    self.sentinel.start()
  File "/usr/local/lib/python3.10/multiprocessing/process.py", line 121, in start
    self._popen = self._Popen(self)
  File "/usr/local/lib/python3.10/multiprocessing/context.py", line 224, in _Popen
    return _default_context.get_context().Process._Popen(process_obj)
  File "/usr/local/lib/python3.10/multiprocessing/context.py", line 277, in _Popen
    return Popen(process_obj)
  File "/usr/local/lib/python3.10/multiprocessing/popen_fork.py", line 19, in __init__
    self._launch(process_obj)
  File "/usr/local/lib/python3.10/multiprocessing/popen_fork.py", line 71, in _launch
    code = process_obj._bootstrap(parent_sentinel=child_r)
  File "/usr/local/lib/python3.10/multiprocessing/process.py", line 315, in _bootstrap
    self.run()
  File "/usr/local/lib/python3.10/multiprocessing/process.py", line 108, in run
    self._target(*self._args, **self._kwargs)
  File "/usr/local/lib/python3.10/site-packages/django_q/cluster.py", line 168, in __init__
    self.start()
  File "/usr/local/lib/python3.10/site-packages/django_q/cluster.py", line 172, in start
    self.spawn_cluster()
  File "/usr/local/lib/python3.10/site-packages/django_q/cluster.py", line 248, in spawn_cluster
    self.pusher = self.spawn_pusher()
  File "/usr/local/lib/python3.10/site-packages/django_q/cluster.py", line 201, in spawn_pusher
    return self.spawn_process(pusher, self.task_queue, self.event_out, self.broker)
  File "/usr/local/lib/python3.10/site-packages/django_q/cluster.py", line 197, in spawn_process
    p.start()
  File "/usr/local/lib/python3.10/multiprocessing/process.py", line 121, in start
    self._popen = self._Popen(self)
  File "/usr/local/lib/python3.10/multiprocessing/context.py", line 224, in _Popen
    return _default_context.get_context().Process._Popen(process_obj)
  File "/usr/local/lib/python3.10/multiprocessing/context.py", line 277, in _Popen
    return Popen(process_obj)
  File "/usr/local/lib/python3.10/multiprocessing/popen_fork.py", line 19, in __init__
    self._launch(process_obj)
  File "/usr/local/lib/python3.10/multiprocessing/popen_fork.py", line 71, in _launch
    code = process_obj._bootstrap(parent_sentinel=child_r)
  File "/usr/local/lib/python3.10/multiprocessing/process.py", line 315, in _bootstrap
    self.run()
  File "/usr/local/lib/python3.10/multiprocessing/process.py", line 108, in run
    self._target(*self._args, **self._kwargs)
  File "/usr/local/lib/python3.10/site-packages/django_q/cluster.py", line 358, in pusher
    logger.error(e, traceback.format_exc())
Message: BadSignature('Signature "AU9Rdt5g7MKNuJZGn2WO4dMQMkcKD4k3a-IPty2EqdQ" does not match')
Arguments: ('Traceback (most recent call last):\n  File "/usr/local/lib/python3.10/site-packages/django_q/cluster.py", line 356, in pusher\n    task = SignedPackage.loads(task[1])\n  File "/usr/local/lib/python3.10/site-packages/django_q/signing.py", line 25, in loads\n    return signing.loads(\n  File "/usr/local/lib/python3.10/site-packages/django_q/core_signing.py", line 35, in loads\n    base64d = force_bytes(TimestampSigner(key, salt=salt).unsign(s, max_age=max_age))\n  File "/usr/local/lib/python3.10/site-packages/django_q/core_signing.py", line 70, in unsign\n    result = super(TimestampSigner, self).unsign(value)\n  File "/usr/local/lib/python3.10/site-packages/django_q/core_signing.py", line 55, in unsign\n    raise BadSignature(\'Signature "%s" does not match\' % sig)\ndjango.core.signing.BadSignature: Signature "AU9Rdt5g7MKNuJZGn2WO4dMQMkcKD4k3a-IPty2EqdQ" does not match\n',)
--- Logging error ---
Traceback (most recent call last):
  File "/usr/local/lib/python3.10/site-packages/django_q/cluster.py", line 356, in pusher
    task = SignedPackage.loads(task[1])
  File "/usr/local/lib/python3.10/site-packages/django_q/signing.py", line 25, in loads
    return signing.loads(
  File "/usr/local/lib/python3.10/site-packages/django_q/core_signing.py", line 35, in loads
    base64d = force_bytes(TimestampSigner(key, salt=salt).unsign(s, max_age=max_age))
  File "/usr/local/lib/python3.10/site-packages/django_q/core_signing.py", line 70, in unsign
    result = super(TimestampSigner, self).unsign(value)
  File "/usr/local/lib/python3.10/site-packages/django_q/core_signing.py", line 55, in unsign
    raise BadSignature('Signature "%s" does not match' % sig)
django.core.signing.BadSignature: Signature "7MB7S_IAnTtKQBQxS2yD7atio4fHNXw8tq0dMZ1UUx4" does not match

During handling of the above exception, another exception occurred:

Traceback (most recent call last):
  File "/usr/local/lib/python3.10/logging/__init__.py", line 1100, in emit
    msg = self.format(record)
  File "/usr/local/lib/python3.10/logging/__init__.py", line 943, in format
    return fmt.format(record)
  File "/usr/local/lib/python3.10/logging/__init__.py", line 678, in format
    record.message = record.getMessage()
  File "/usr/local/lib/python3.10/logging/__init__.py", line 368, in getMessage
    msg = msg % self.args
TypeError: not all arguments converted during string formatting
Call stack:
  File "/home/VideoWatchEarnBot/server/manage.py", line 22, in <module>
    main()
  File "/home/VideoWatchEarnBot/server/manage.py", line 18, in main
    execute_from_command_line(sys.argv)
  File "/usr/local/lib/python3.10/site-packages/django/core/management/__init__.py", line 446, in execute_from_command_line
    utility.execute()
  File "/usr/local/lib/python3.10/site-packages/django/core/management/__init__.py", line 440, in execute
    self.fetch_command(subcommand).run_from_argv(self.argv)
  File "/usr/local/lib/python3.10/site-packages/django/core/management/base.py", line 414, in run_from_argv
    self.execute(*args, **cmd_options)
  File "/usr/local/lib/python3.10/site-packages/django/core/management/base.py", line 460, in execute
    output = self.handle(*args, **options)
  File "/usr/local/lib/python3.10/site-packages/django_q/management/commands/qcluster.py", line 22, in handle
    q.start()
  File "/usr/local/lib/python3.10/site-packages/django_q/cluster.py", line 78, in start
    self.sentinel.start()
  File "/usr/local/lib/python3.10/multiprocessing/process.py", line 121, in start
    self._popen = self._Popen(self)
  File "/usr/local/lib/python3.10/multiprocessing/context.py", line 224, in _Popen
    return _default_context.get_context().Process._Popen(process_obj)
  File "/usr/local/lib/python3.10/multiprocessing/context.py", line 277, in _Popen
    return Popen(process_obj)
  File "/usr/local/lib/python3.10/multiprocessing/popen_fork.py", line 19, in __init__
    self._launch(process_obj)
  File "/usr/local/lib/python3.10/multiprocessing/popen_fork.py", line 71, in _launch
    code = process_obj._bootstrap(parent_sentinel=child_r)
  File "/usr/local/lib/python3.10/multiprocessing/process.py", line 315, in _bootstrap
    self.run()
  File "/usr/local/lib/python3.10/multiprocessing/process.py", line 108, in run
    self._target(*self._args, **self._kwargs)
  File "/usr/local/lib/python3.10/site-packages/django_q/cluster.py", line 168, in __init__
    self.start()
  File "/usr/local/lib/python3.10/site-packages/django_q/cluster.py", line 172, in start
    self.spawn_cluster()
  File "/usr/local/lib/python3.10/site-packages/django_q/cluster.py", line 248, in spawn_cluster
    self.pusher = self.spawn_pusher()
  File "/usr/local/lib/python3.10/site-packages/django_q/cluster.py", line 201, in spawn_pusher
    return self.spawn_process(pusher, self.task_queue, self.event_out, self.broker)
  File "/usr/local/lib/python3.10/site-packages/django_q/cluster.py", line 197, in spawn_process
    p.start()
  File "/usr/local/lib/python3.10/multiprocessing/process.py", line 121, in start
    self._popen = self._Popen(self)
  File "/usr/local/lib/python3.10/multiprocessing/context.py", line 224, in _Popen
    return _default_context.get_context().Process._Popen(process_obj)
  File "/usr/local/lib/python3.10/multiprocessing/context.py", line 277, in _Popen
    return Popen(process_obj)
  File "/usr/local/lib/python3.10/multiprocessing/popen_fork.py", line 19, in __init__
    self._launch(process_obj)
  File "/usr/local/lib/python3.10/multiprocessing/popen_fork.py", line 71, in _launch
    code = process_obj._bootstrap(parent_sentinel=child_r)
  File "/usr/local/lib/python3.10/multiprocessing/process.py", line 315, in _bootstrap
    self.run()
  File "/usr/local/lib/python3.10/multiprocessing/process.py", line 108, in run
    self._target(*self._args, **self._kwargs)
  File "/usr/local/lib/python3.10/site-packages/django_q/cluster.py", line 358, in pusher
    logger.error(e, traceback.format_exc())
Message: BadSignature('Signature "7MB7S_IAnTtKQBQxS2yD7atio4fHNXw8tq0dMZ1UUx4" does not match')
Arguments: ('Traceback (most recent call last):\n  File "/usr/local/lib/python3.10/site-packages/django_q/cluster.py", line 356, in pusher\n    task = SignedPackage.loads(task[1])\n  File "/usr/local/lib/python3.10/site-packages/django_q/signing.py", line 25, in loads\n    return signing.loads(\n  File "/usr/local/lib/python3.10/site-packages/django_q/core_signing.py", line 35, in loads\n    base64d = force_bytes(TimestampSigner(key, salt=salt).unsign(s, max_age=max_age))\n  File "/usr/local/lib/python3.10/site-packages/django_q/core_signing.py", line 70, in unsign\n    result = super(TimestampSigner, self).unsign(value)\n  File "/usr/local/lib/python3.10/site-packages/django_q/core_signing.py", line 55, in unsign\n    raise BadSignature(\'Signature "%s" does not match\' % sig)\ndjango.core.signing.BadSignature: Signature "7MB7S_IAnTtKQBQxS2yD7atio4fHNXw8tq0dMZ1UUx4" does not match\n',)
--- Logging error ---
Traceback (most recent call last):
  File "/usr/local/lib/python3.10/site-packages/django_q/cluster.py", line 356, in pusher
    task = SignedPackage.loads(task[1])
  File "/usr/local/lib/python3.10/site-packages/django_q/signing.py", line 25, in loads
    return signing.loads(
  File "/usr/local/lib/python3.10/site-packages/django_q/core_signing.py", line 35, in loads
    base64d = force_bytes(TimestampSigner(key, salt=salt).unsign(s, max_age=max_age))
  File "/usr/local/lib/python3.10/site-packages/django_q/core_signing.py", line 70, in unsign
    result = super(TimestampSigner, self).unsign(value)
  File "/usr/local/lib/python3.10/site-packages/django_q/core_signing.py", line 55, in unsign
    raise BadSignature('Signature "%s" does not match' % sig)
django.core.signing.BadSignature: Signature "QUtBi8egaUPfkJuOjJ9yVx0A_15T0W-DD6TxPXzo6RI" does not match

During handling of the above exception, another exception occurred:

Traceback (most recent call last):
  File "/usr/local/lib/python3.10/logging/__init__.py", line 1100, in emit
    msg = self.format(record)
  File "/usr/local/lib/python3.10/logging/__init__.py", line 943, in format
    return fmt.format(record)
  File "/usr/local/lib/python3.10/logging/__init__.py", line 678, in format
    record.message = record.getMessage()
  File "/usr/local/lib/python3.10/logging/__init__.py", line 368, in getMessage
    msg = msg % self.args
TypeError: not all arguments converted during string formatting
Call stack:
  File "/home/VideoWatchEarnBot/server/manage.py", line 22, in <module>
    main()
  File "/home/VideoWatchEarnBot/server/manage.py", line 18, in main
    execute_from_command_line(sys.argv)
  File "/usr/local/lib/python3.10/site-packages/django/core/management/__init__.py", line 446, in execute_from_command_line
    utility.execute()
  File "/usr/local/lib/python3.10/site-packages/django/core/management/__init__.py", line 440, in execute
    self.fetch_command(subcommand).run_from_argv(self.argv)
  File "/usr/local/lib/python3.10/site-packages/django/core/management/base.py", line 414, in run_from_argv
    self.execute(*args, **cmd_options)
  File "/usr/local/lib/python3.10/site-packages/django/core/management/base.py", line 460, in execute
    output = self.handle(*args, **options)
  File "/usr/local/lib/python3.10/site-packages/django_q/management/commands/qcluster.py", line 22, in handle
    q.start()
  File "/usr/local/lib/python3.10/site-packages/django_q/cluster.py", line 78, in start
    self.sentinel.start()
  File "/usr/local/lib/python3.10/multiprocessing/process.py", line 121, in start
    self._popen = self._Popen(self)
  File "/usr/local/lib/python3.10/multiprocessing/context.py", line 224, in _Popen
    return _default_context.get_context().Process._Popen(process_obj)
  File "/usr/local/lib/python3.10/multiprocessing/context.py", line 277, in _Popen
    return Popen(process_obj)
  File "/usr/local/lib/python3.10/multiprocessing/popen_fork.py", line 19, in __init__
    self._launch(process_obj)
  File "/usr/local/lib/python3.10/multiprocessing/popen_fork.py", line 71, in _launch
    code = process_obj._bootstrap(parent_sentinel=child_r)
  File "/usr/local/lib/python3.10/multiprocessing/process.py", line 315, in _bootstrap
    self.run()
  File "/usr/local/lib/python3.10/multiprocessing/process.py", line 108, in run
    self._target(*self._args, **self._kwargs)
  File "/usr/local/lib/python3.10/site-packages/django_q/cluster.py", line 168, in __init__
    self.start()
  File "/usr/local/lib/python3.10/site-packages/django_q/cluster.py", line 172, in start
    self.spawn_cluster()
  File "/usr/local/lib/python3.10/site-packages/django_q/cluster.py", line 248, in spawn_cluster
    self.pusher = self.spawn_pusher()
  File "/usr/local/lib/python3.10/site-packages/django_q/cluster.py", line 201, in spawn_pusher
    return self.spawn_process(pusher, self.task_queue, self.event_out, self.broker)
  File "/usr/local/lib/python3.10/site-packages/django_q/cluster.py", line 197, in spawn_process
    p.start()
  File "/usr/local/lib/python3.10/multiprocessing/process.py", line 121, in start
    self._popen = self._Popen(self)
  File "/usr/local/lib/python3.10/multiprocessing/context.py", line 224, in _Popen
    return _default_context.get_context().Process._Popen(process_obj)
  File "/usr/local/lib/python3.10/multiprocessing/context.py", line 277, in _Popen
    return Popen(process_obj)
  File "/usr/local/lib/python3.10/multiprocessing/popen_fork.py", line 19, in __init__
    self._launch(process_obj)
  File "/usr/local/lib/python3.10/multiprocessing/popen_fork.py", line 71, in _launch
    code = process_obj._bootstrap(parent_sentinel=child_r)
  File "/usr/local/lib/python3.10/multiprocessing/process.py", line 315, in _bootstrap
    self.run()
  File "/usr/local/lib/python3.10/multiprocessing/process.py", line 108, in run
    self._target(*self._args, **self._kwargs)
  File "/usr/local/lib/python3.10/site-packages/django_q/cluster.py", line 358, in pusher
    logger.error(e, traceback.format_exc())
Message: BadSignature('Signature "QUtBi8egaUPfkJuOjJ9yVx0A_15T0W-DD6TxPXzo6RI" does not match')
Arguments: ('Traceback (most recent call last):\n  File "/usr/local/lib/python3.10/site-packages/django_q/cluster.py", line 356, in pusher\n    task = SignedPackage.loads(task[1])\n  File "/usr/local/lib/python3.10/site-packages/django_q/signing.py", line 25, in loads\n    return signing.loads(\n  File "/usr/local/lib/python3.10/site-packages/django_q/core_signing.py", line 35, in loads\n    base64d = force_bytes(TimestampSigner(key, salt=salt).unsign(s, max_age=max_age))\n  File "/usr/local/lib/python3.10/site-packages/django_q/core_signing.py", line 70, in unsign\n    result = super(TimestampSigner, self).unsign(value)\n  File "/usr/local/lib/python3.10/site-packages/django_q/core_signing.py", line 55, in unsign\n    raise BadSignature(\'Signature "%s" does not match\' % sig)\ndjango.core.signing.BadSignature: Signature "QUtBi8egaUPfkJuOjJ9yVx0A_15T0W-DD6TxPXzo6RI" does not match\n',)
--- Logging error ---
Traceback (most recent call last):
  File "/usr/local/lib/python3.10/site-packages/django_q/cluster.py", line 356, in pusher
    task = SignedPackage.loads(task[1])
  File "/usr/local/lib/python3.10/site-packages/django_q/signing.py", line 25, in loads
    return signing.loads(
  File "/usr/local/lib/python3.10/site-packages/django_q/core_signing.py", line 35, in loads
    base64d = force_bytes(TimestampSigner(key, salt=salt).unsign(s, max_age=max_age))
  File "/usr/local/lib/python3.10/site-packages/django_q/core_signing.py", line 70, in unsign
    result = super(TimestampSigner, self).unsign(value)
  File "/usr/local/lib/python3.10/site-packages/django_q/core_signing.py", line 55, in unsign
    raise BadSignature('Signature "%s" does not match' % sig)
django.core.signing.BadSignature: Signature "q809Yp6T82Ce674cwCqVZA_-KH0q9siO6AXiUcL920c" does not match

During handling of the above exception, another exception occurred:

Traceback (most recent call last):
  File "/usr/local/lib/python3.10/logging/__init__.py", line 1100, in emit
    msg = self.format(record)
  File "/usr/local/lib/python3.10/logging/__init__.py", line 943, in format
    return fmt.format(record)
  File "/usr/local/lib/python3.10/logging/__init__.py", line 678, in format
    record.message = record.getMessage()
  File "/usr/local/lib/python3.10/logging/__init__.py", line 368, in getMessage
    msg = msg % self.args
TypeError: not all arguments converted during string formatting
Call stack:
  File "/home/VideoWatchEarnBot/server/manage.py", line 22, in <module>
    main()
  File "/home/VideoWatchEarnBot/server/manage.py", line 18, in main
    execute_from_command_line(sys.argv)
  File "/usr/local/lib/python3.10/site-packages/django/core/management/__init__.py", line 446, in execute_from_command_line
    utility.execute()
  File "/usr/local/lib/python3.10/site-packages/django/core/management/__init__.py", line 440, in execute
    self.fetch_command(subcommand).run_from_argv(self.argv)
  File "/usr/local/lib/python3.10/site-packages/django/core/management/base.py", line 414, in run_from_argv
    self.execute(*args, **cmd_options)
  File "/usr/local/lib/python3.10/site-packages/django/core/management/base.py", line 460, in execute
    output = self.handle(*args, **options)
  File "/usr/local/lib/python3.10/site-packages/django_q/management/commands/qcluster.py", line 22, in handle
    q.start()
  File "/usr/local/lib/python3.10/site-packages/django_q/cluster.py", line 78, in start
    self.sentinel.start()
  File "/usr/local/lib/python3.10/multiprocessing/process.py", line 121, in start
    self._popen = self._Popen(self)
  File "/usr/local/lib/python3.10/multiprocessing/context.py", line 224, in _Popen
    return _default_context.get_context().Process._Popen(process_obj)
  File "/usr/local/lib/python3.10/multiprocessing/context.py", line 277, in _Popen
    return Popen(process_obj)
  File "/usr/local/lib/python3.10/multiprocessing/popen_fork.py", line 19, in __init__
    self._launch(process_obj)
  File "/usr/local/lib/python3.10/multiprocessing/popen_fork.py", line 71, in _launch
    code = process_obj._bootstrap(parent_sentinel=child_r)
  File "/usr/local/lib/python3.10/multiprocessing/process.py", line 315, in _bootstrap
    self.run()
  File "/usr/local/lib/python3.10/multiprocessing/process.py", line 108, in run
    self._target(*self._args, **self._kwargs)
  File "/usr/local/lib/python3.10/site-packages/django_q/cluster.py", line 168, in __init__
    self.start()
  File "/usr/local/lib/python3.10/site-packages/django_q/cluster.py", line 172, in start
    self.spawn_cluster()
  File "/usr/local/lib/python3.10/site-packages/django_q/cluster.py", line 248, in spawn_cluster
    self.pusher = self.spawn_pusher()
  File "/usr/local/lib/python3.10/site-packages/django_q/cluster.py", line 201, in spawn_pusher
    return self.spawn_process(pusher, self.task_queue, self.event_out, self.broker)
  File "/usr/local/lib/python3.10/site-packages/django_q/cluster.py", line 197, in spawn_process
    p.start()
  File "/usr/local/lib/python3.10/multiprocessing/process.py", line 121, in start
    self._popen = self._Popen(self)
  File "/usr/local/lib/python3.10/multiprocessing/context.py", line 224, in _Popen
    return _default_context.get_context().Process._Popen(process_obj)
  File "/usr/local/lib/python3.10/multiprocessing/context.py", line 277, in _Popen
    return Popen(process_obj)
  File "/usr/local/lib/python3.10/multiprocessing/popen_fork.py", line 19, in __init__
    self._launch(process_obj)
  File "/usr/local/lib/python3.10/multiprocessing/popen_fork.py", line 71, in _launch
    code = process_obj._bootstrap(parent_sentinel=child_r)
  File "/usr/local/lib/python3.10/multiprocessing/process.py", line 315, in _bootstrap
    self.run()
  File "/usr/local/lib/python3.10/multiprocessing/process.py", line 108, in run
    self._target(*self._args, **self._kwargs)
  File "/usr/local/lib/python3.10/site-packages/django_q/cluster.py", line 358, in pusher
    logger.error(e, traceback.format_exc())
Message: BadSignature('Signature "q809Yp6T82Ce674cwCqVZA_-KH0q9siO6AXiUcL920c" does not match')
Arguments: ('Traceback (most recent call last):\n  File "/usr/local/lib/python3.10/site-packages/django_q/cluster.py", line 356, in pusher\n    task = SignedPackage.loads(task[1])\n  File "/usr/local/lib/python3.10/site-packages/django_q/signing.py", line 25, in loads\n    return signing.loads(\n  File "/usr/local/lib/python3.10/site-packages/django_q/core_signing.py", line 35, in loads\n    base64d = force_bytes(TimestampSigner(key, salt=salt).unsign(s, max_age=max_age))\n  File "/usr/local/lib/python3.10/site-packages/django_q/core_signing.py", line 70, in unsign\n    result = super(TimestampSigner, self).unsign(value)\n  File "/usr/local/lib/python3.10/site-packages/django_q/core_signing.py", line 55, in unsign\n    raise BadSignature(\'Signature "%s" does not match\' % sig)\ndjango.core.signing.BadSignature: Signature "q809Yp6T82Ce674cwCqVZA_-KH0q9siO6AXiUcL920c" does not match\n',)
